<?xml version="1.0" encoding="utf-8"?><testsuites><testsuite name="pytest" errors="0" failures="0" skipped="1" tests="11" time="4.926" timestamp="2025-08-19T12:58:42.156056" hostname="N2202942"><testcase classname="tests.manual_connection_test" name="test_ea_connection" time="1.466" /><testcase classname="tests.manual_package_test" name="test_package_functions" time="0.005" /><testcase classname="tests.test_cli_mock" name="test_cli_arguments" time="0.025" /><testcase classname="tests.test_cli_mock" name="test_cli_with_mock" time="1.967" /><testcase classname="tests.test_ea_connection.TestEAConnection" name="test_real_ea_connection" time="1.260"><skipped type="pytest.skip" message="EA nicht verfügbar: (-2147352567, 'Ausnahmefehler aufgetreten.', (61704, 'Enterprise Architect', 'Internal application error.', None, 0, 0), None)">C:\Users\E017093\gitRepos\EA_COM_Automation\tests\test_ea_connection.py:95: EA nicht verfügbar: (-2147352567, 'Ausnahmefehler aufgetreten.', (61704, 'Enterprise Architect', 'Internal application error.', None, 0, 0), None)</skipped></testcase><testcase classname="tests.test_ea_connection.TestEAConnection" name="test_mock_ea_repository" time="0.003" /><testcase classname="tests.test_ea_connection.TestEAConnection" name="test_create_package_with_mock" time="0.002" /><testcase classname="tests.test_ea_connection.TestEAConnection" name="test_ensure_path_with_mock" time="0.006" /><testcase classname="tests.test_ea_connection.TestEAConnection" name="test_ensure_path_idempotence" time="0.003" /><testcase classname="tests.test_ea_connection.TestEAConnection" name="test_error_handling" time="0.002" /><testcase classname="tests.integration.test_full_workflow.TestFullWorkflow" name="test_complete_project_setup" time="0.016" /></testsuite></testsuites>